Workbook
Name Alineamiento: 'A-D.- FICHA'!$G$50:$H$52
Name Alineamiento: #REF!
Name CatTipo: 'A-D.- FICHA'!$E$134:$R$134
Name CatTipo: #REF!
Name Cond.Borde: 'A-D.- FICHA'!$C$145:$C$151
Name Cond.Borde: #REF!
Name Cond.Carretera: 'A-D.- FICHA'!$J$376:$J$378
Name Cond.Carretera: #REF!
Name CondAmb: 'A-D.- FICHA'!$N$50:$N$52
Name CondAmb: #REF!
Name elementos: #REF!
Name FormaViga: 'A-D.- FICHA'!$L$154:$L$157
Name FormaViga: #REF!
Name luisa: 'A-D.- FICHA'!$C$162:$C$166
Name luisa: #REF!
Name MarcasdeCalzada: 'A-D.- FICHA'!$G$373
Name MarcasdeCalzada: #REF!
Name Mat: 'A-D.- FICHA'!$G$162:$G$165
Name Mat: #REF!
Name Mat.Predo: 'A-D.- FICHA'!$G$145:$G$151
Name Mat.Predo: #REF!
Name MatBaranda: 'A-D.- FICHA'!$G$283:$G$286
Name MatBaranda: #REF!
Name MatDrenaje: 'A-D.- FICHA'!$M$291:$M$294
Name MatDrenaje: #REF!
Name MaterialCimenta: 'A-D.- FICHA'!$N$162:$N$166
Name MaterialCimenta: #REF!
Name MaterialEleva: 'A-D.- FICHA'!$G$162:$G$165
Name MaterialEleva: #REF!
Name Materiallosa: 'A-D.- FICHA'!$J$145:$J$149
Name Materiallosa: #REF!
Name MatJuntas: 'A-D.- FICHA'!$F$291:$F$294
Name MatJuntas: #REF!
Name MatVeredas: 'A-D.- FICHA'!$J$283:$J$285
Name MatVeredas: #REF!
Name MatVigas: 'A-D.- FICHA'!$H$154:$H$158
Name MatVigas: #REF!
Name Nat.Suelo: 'A-D.- FICHA'!$N$376:$N$381
Name Nat.Suelo: #REF!
Name pendiente: #REF!
Name pendiente: #REF!
Name SeñaCarga: #REF!
Name SeñaCarga: #REF!
Name SeñalInformativa: 'A-D.- FICHA'!$G$361
Name SeñalInformativa: #REF!
Name Señalpreventiva: 'A-D.- FICHA'!$G$363:$G$366
Name Señalpreventiva: #REF!
Name SeñalReglamentaria: 'A-D.- FICHA'!$G$368:$G$371
Name SeñalReglamentaria: #REF!
Name Sobre: 'A-D.- FICHA'!$C$50:$E$57
Name Sobre: #REF!
Name Subestructura: 'A-D.- FICHA'!$G$376:$G$377
Name Subestructura: #REF!
Name SuperDesgaste: 'A-D.- FICHA'!$N$145:$N$149
Name SuperDesgaste: #REF!
Name TipoApoyos: 'A-D.- FICHA'!$N$283:$N$288
Name TipoApoyos: #REF!
Name TipoBarandas: 'A-D.- FICHA'!$C$283:$C$286
Name TipoBarandas: #REF!
Name TipoCimentación: 'A-D.- FICHA'!$J$162:$J$165

Sheet A-D.- FICHA
F1: SERVICIO DE CONSULTORIA PARA EL INVENTARIO ESPECIALIZADO DE LA INFRAESTRUCTURA VIAL EN LOS TRAMOS DE LA RED VIAL NACIONAL NO CONCESIONADA
C4: FICHA SCAP
C7: SECCION (A) : IDENTIFICACIÓN Y UBICACIÓN
H10: Nombre | J10: AUDITORIA LOSA | N10: 1
H12: Código | J12: P-NEW | N12: 2
C14: Altitud: | G14: 3 | H14: Dpto Político: | L14: 6 | N14: Pob. mas cercano | P14: =+J20 | R14: 10
C16: Latitud | E16: -12.75 | G16: 4 | H16: Dpto Vial | L16: 7 | N16: Ruta | P16: PE-28H | R16: 11
C18: Longitud | E18: -77.5 | G18: 5 | H18: Provincia | L18: 8 | N18: Kilometraje | P18: 42125.5 | R18: 12
H20: Distrito | L20: 9 | N20: Tipo de Ruta | R20: 13
C25: SECCION (B): DATOS GENERALES
C28: Puente sobre: | G28: 1 | J28: Número de Proyecto: | P28: 10
C30: Nombre: | G30: 2 | J30: Año de Construcción: | P30: 11
C32: Longitud Total: | E32: 18.4 | G32: 3 | J32: Última Inspección: | N32: 46302 | P32: 12 | R32: mm/dd/aa
C34: Num de vías de tránsito: | G34: 4 | J34: Último Trabajo: | P34: 13
C36: Ancho de Calzada: | G36: 5 | J36: Tipo de Servicio: | R36: 14
C38: Sobrecarga de Diseño: | G38: 6 | J38: Flujo de Tráfico: | P38: 15
C40: Ancho de Vereda: | G40: 7 | J40: Año: | P40: 16
C42: Altura Libre Superior: | G42: 8 | J42: % Camiones y Buses: | P42: 17
C44: Altura Libre Inferior: | G44: 9 | J44: Alineamiento: | P44: 18
J46: Condiciones Ambientales: | P46: 19
C49: Sobre | G49: Alineamiento | J49: Tipo de Servicio | N49: Condiciones Ambientales
C50: Río | G50: Recto | J50: Irrestricto | N50: Severo
C51: Quebrada Seca | G51: Curvo | J51: Solo Automoviles | N51: Moderado | R51: Tipo de ruta
C52: Quebrada | G52: Esviado | J52: Solo Camiones | N52: Benigno | R52: Nacional
C53: Canal | J53: Camiones hasta Cierta Carga | R53: Departamental
C54: Carretera | J54: Fuera de Servicio | R54: Vecinal
C55: FFCC
C56: Valle (Viaducto Elevado)
C57: Zona Urbana (Viaducto elevado)
C60: SECCION (C): DATOS DEL PUENTE
C63: Num Tram: | G63: 1 | H63: Long. 1ºTramo: | J63: =+E67 | L63: 4
C65: Tramos: | G65: 2 | H65: Long. 2ºTramo: | L65: 5
C67: Longitud Total: | E67: =+E32 | G67: (Igual a B-3) | H67: Long. 3ºTramo: | L67: 6
C69: Luz Principal: | G69: 3
C73: C.1 : TRAMO 1 (PRINCIPAL) | J73: C.2 :TRAMO 2
C75: {Sección 1} | J75: {Sección 2} | L75: =+IF(E65="Desiguales","","(igual a Sección 1)") | U75: DEFINITIVO
C76: {Subsección a} | U76: Losa
C77: Categoría: | G77: 1 | J77: Categoría: | P77: 1 | U77: Losa con Vigas
U78: Portico
C79: Tipo : | G79: 2 | J79: Tipo : | P79: 2 | U79: Arco
...

Sheet E.- CROQUIS
D2: SERVICIO DE CONSULTORIA PARA EL INVENTARIO ESPECIALIZADO DE LA INFRAESTRUCTURA VIAL EN LOS TRAMOS DE LA RED VIAL NACIONAL NO CONCESIONADA
A5: FICHA SCAP
B8: SECCION ( E ) : CROQUIS DEL PUENTE
B9: NOMBRE : | C9: =+'A-D.- FICHA'!J10
B10: Ruta : | C10: =+'A-D.- FICHA'!P16 | H10: Progresiva : | I10: =+'A-D.- FICHA'!P18
B12: ELEVACION
B26: PLANTA
B41: SECCION TRANSVERSAL
B55: =+'A-D.- FICHA'!C48

Sheet F.1- CONDICION GLOBAL
E1: SERVICIO DE CONSULTORIA PARA EL INVENTARIO ESPECIALIZADO DE LA INFRAESTRUCTURA VIAL EN LOS TRAMOS DE LA RED VIAL NACIONAL NO CONCESIONADA
A4: FICHA SCAP
A5: SECCION (F): CONDICION DEL PUENTE
C6: Puente : | D6: =+#REF! | F6: Ruta : | G6: =+'A-D.- FICHA'!P16 | I6: Progresiva: | K6: =+'A-D.- FICHA'!P18
C8: F.2 :CONDICION GLOBAL DEL PUENTE
D11: 1 | E11: Bueno | G11: 3 | H11: Preocupante | J11: 5 | K11: Pesimo
D13: 0 | E13: Excelente | G13: 2 | H13: Regular | J13: 4 | K13: Malo
C15: Inspector | D15: Inspector | H15: Fecha de Inspeccion | K15: ='A-D.- FICHA'!N32
C16: Supervisor | H16: Fecha de Revision
C19: Elemento | F19: Descripcion
B21: I. SUPERESTRUCTURA
B25: II. SUBESTRUCTURA
B30: III. DETALLES
B35: IV. CAUCE
B40: V. ACCESOS
B41: X-01 | C41: Elemento manual campo

Sheet F.2.-PANEL FOTOGRAFICO
D1: SERVICIO DE CONSULTORIA PARA EL INVENTARIO ESPECIALIZADO DE LA INFRAESTRUCTURA VIAL EN LOS TRAMOS DE LA RED VIAL NACIONAL NO CONCESIONADA
B3: F.2 PANEL FOTOGRAFICO | XFD3: SI
XFD4: NO
B5: NOMBRE | D5: =+'A-D.- FICHA'!J10
B6: RUTA | D6: =+'A-D.- FICHA'!P16
B7: PROGRESIVA | D7: =+'A-D.- FICHA'!P18
B9: LISTA DE FOTOGRAFIAS
B10: NRO. | C10: FECHA | D10: DESCRIPCION | E10: DIGITAL
B11: 1 | C11: 46304 | D11: Vista general: Fotografia sintetica limpia

Sheet G.- CONDICION ESTADISTICA
C1: SERVICIO DE CONSULTORIA PARA EL INVENTARIO ESPECIALIZADO DE LA INFRAESTRUCTURA VIAL EN LOS TRAMOS DE LA RED VIAL NACIONAL NO CONCESIONADA
A3: =+'A-D.- FICHA'!C4
A5: G.1 : CONDICION ESTADISTICA DEL PUENTE
A7: =+CONCATENATE("NOMBRE: ",'A-D.- FICHA'!J10) | E7: Ruta: | F7: =+'A-D.- FICHA'!P16 | J7: PROGRESIVA : | M7: =+'A-D.- FICHA'!P18
A9: tabla 1
A10: CODIGO | B10: DESCRIPCION | D10: METRADO | E10: UND. | F10: Factor de Importancia | G10: CALIFICACION (%) | M10: CONDICION ESTADISTICA DEL PUENTE
G11: 0 | H11: 1 | I11: 2 | J11: 3 | K11: 4 | L11: 5
G12: Muy Bueno | H12: Bueno | I12: Satisfactorio | J12: Marginal | K12: Pobre | L12: Muy Pobre | N12: =IF(M13>4,"MUY MALO",IF(M13>3,"MALO",IF(M13>2,"REGULAR","BUENO")))
M13: =+F191 | O13: verificaciones
A14: X-01 | B14: Elemento manual campo | D14: 12.75 | E14: ml | F14: 0.8 | G14: 0 | H14: 80 | I14: 20 | J14: 0 | K14: 0 | L14: 0 | O14: =SUM(G14:L14) | P14: =+IF(O14<=100,+IF(O14=100,"Ok",""),"se pasa")
O15: =SUM(G15:L15) | P15: =+IF(O15<=100,+IF(O15=100,"Ok",""),"se pasa")
O16: =SUM(G16:L16) | P16: =+IF(O16<=100,+IF(O16=100,"Ok",""),"se pasa")
O17: =SUM(G17:L17) | P17: =+IF(O17<=100,+IF(O17=100,"Ok",""),"se pasa")
O18: =SUM(G18:L18) | P18: =+IF(O18<=100,+IF(O18=100,"Ok",""),"se pasa")
O19: =SUM(G19:L19) | P19: =+IF(O19<=100,+IF(O19=100,"Ok",""),"se pasa")
O20: =SUM(G20:L20) | P20: =+IF(O20<=100,+IF(O20=100,"Ok",""),"se pasa")
O21: =SUM(G21:L21) | P21: =+IF(O21<=100,+IF(O21=100,"Ok",""),"se pasa")
O22: =SUM(G22:L22) | P22: =+IF(O22<=100,+IF(O22=100,"Ok",""),"se pasa")
O23: =SUM(G23:L23) | P23: =+IF(O23<=100,+IF(O23=100,"Ok",""),"se pasa")
O24: =SUM(G24:L24) | P24: =+IF(O24<=100,+IF(O24=100,"Ok",""),"se pasa")
O25: =SUM(G25:L25) | P25: =+IF(O25<=100,+IF(O25=100,"Ok",""),"se pasa")
O26: =SUM(G26:L26) | P26: =+IF(O26<=100,+IF(O26=100,"Ok",""),"se pasa")
... O36: =SUM(G36:L36) | P36: =+IF(O36<=100,+IF(O36=100,"Ok",""),"se pasa")
O46: SI(A26=0," ",BUSCARV(A26,'CONDICION ESTADISTICA'!$B$143:$D$235,3))
A48: tabla 2 | C48: AJUSTES DE PORCENTAJE POR UMBRAL (%campo * 100 / %umbral) | G48: 25 | H48: 25 | I48: 25 | J48: 25 | K48: 25 | L48: 3
A49: NRO. | C49: DESCRIPCION | G49: CALIFICACION | M49: OBSERVACIONES
G50: 0 | H50: 1 | I50: 2 | J50: 3 | K50: 4 | L50: 5
A51: =+A14 | C51: =+B14 | G51: =+G14/G$48*100 | H51: =+H14/H$48*100 | I51: =+I14/I$48*100 | J51: =+J14/J$48*100 | K51: =+K14/K$48*100 | L51: =+L14/L$48*100
A52: =+A15 | C52: =+B15 | G52: =+G15/G$48*100 | H52: =+H15/H$48*100 | I52: =+I15/I$48*100 | J52: =+J15/J$48*100 | K52: =+K15/K$48*100 | L52: =+L15/L$48*100
A53: =+A16 | C53: =+B16 | G53: =+G16/G$48*100 | H53: =+H16/H$48*100 | I53: =+I16/I$48*100 | J53: =+J16/J$48*100 | K53: =+K16/K$48*100 | L53: =+L16/L$48*100
A54: =+A17 | C54: =+B17 | G54: =+G17/G$48*100 | H54: =+H17/H$48*100 | I54: =+I17/I$48*100 | J54: =+J17/J$48*100 | K54: =+K17/K$48*100 | L54: =+L17/L$48*100
A55: =+A18 | C55: =+B18 | G55: =+G18/G$48*100 | H55: =+H18/H$48*100 | I55: =+I18/I$48*100 | J55: =+J18/J$48*100 | K55: =+K18/K$48*100 | L55: =+L18/L$48*100
A56: =+A19 | C56: =+B19 | G56: =+G19/G$48*100 | H56: =+H19/H$48*100 | I56: =+I19/I$48*100 | J56: =+J19/J$48*100 | K56: =+K19/K$48*100 | L56: =+L19/L$48*100
A57: =+A20 | C57: =+B20 | G57: =+G20/G$48*100 | H57: =+H20/H$48*100 | I57: =+I20/I$48*100 | J57: =+J20/J$48*100 | K57: =+K20/K$48*100 | L57: =+L20/L$48*100
A58: =+A21 | C58: =+B21 | G58: =+G21/G$48*100 | H58: =+H21/H$48*100 | I58: =+I21/I$48*100 | J58: =+J21/J$48*100 | K58: =+K21/K$48*100 | L58: =+L21/L$48*100
A59: =+A22 | C59: =+B22 | G59: =+G22/G$48*100 | H59: =+H22/H$48*100 | I59: =+I22/I$48*100 | J59: =+J22/J$48*100 | K59: =+K22/K$48*100 | L59: =+L22/L$48*100
A60: =+A23 | C60: =+B23 | G60: =+G23/G$48*100 | H60: =+H23/H$48*100 | I60: =+I23/I$48*100 | J60: =+J23/J$48*100 | K60: =+K23/K$48*100 | L60: =+L23/L$48*100
A61: =+A24 | C61: =+B24 | G61: =+G24/G$48*100 | H61: =+H24/H$48*100 | I61: =+I24/I$48*100 | J61: =+J24/J$48*100 | K61: =+K24/K$48*100 | L61: =+L24/L$48*100
A62: =+A25 | C62: =+B25 | G62: =+G25/G$48*100 | H62: =+H25/H$48*100 | I62: =+I25/I$48*100 | J62: =+J25/J$48*100 | K62: =+K25/K$48*100 | L62: =+L25/L$48*100
... A64: =+A27 | C64: =+B27 | G64: =+G27/G$48*100 | H64: =+H27/H$48*100 | I64: =+I27/I$48*100 | J64: =+J27/J$48*100 | K64: =+K27/K$48*100 | L64: =+L27/L$48*100
...

Sheet G.2-CONCLUSIONES
D1: SERVICIO DE CONSULTORIA PARA EL INVENTARIO ESPECIALIZADO DE LA INFRAESTRUCTURA VIAL EN LOS TRAMOS DE LA RED VIAL NACIONAL NO CONCESIONADA
B4: FICHA SCAP
B6: SECCION (G): RESUMEN DE LA CONDICION DEL PUENTE Y RECOMENDACIONES
C9: G.2 : OBSERVACIONES Y RECOMENDACIONES
B12: NOMBRE | D12: =+Hoja3!C11
B13: RUTA | D13: =+Hoja3!C7
B14: PROGRESIVA | D14: =+Hoja3!C10
B17: OBSERVACIONES | F17: RECOMENDACIONES
B18: ACCIONES NORMATIVAS :
B19: =_xlfn.CONCAT("De acuerdo a la evaluación realizada al ",'A-D.- FICHA'!J10:L10," y a los terminos de referencia (Gestión y relevamiento de Puentes); de ser necesario, corresponde realizar acciones normativas.")
B28: ACCIONES PREVENTIVAS :
B29: =+_xlfn.CONCAT("De acuerdo a la evaluación realizada al Puente ",'A-D.- FICHA'!J10:L10," y a los terminos de referencia (Gestión y Relevamiento de Puentes); de ser necesario, corresponde realizar acciones preventivas.")
B38: ACCIONES EJECUTIVAS :
B39: =_xlfn.CONCAT("De la inspeccion realizada podemos indicar las siguientes conclusiones:", " La evaluación de la condición estadística del ",'A-D.- FICHA'!J10:L10, ", efectuada bajo la metodología SCAP señala que el puente se encuentra en la calificación ",'G.- CONDICION ESTADISTICA'!N12," requiriéndose realizar el mantenimiento rutinario a fin de mejorar e incrementar su vida útil, a continuacion detallamos las acciones a realizar.") | E39: =_xlfn.CONCAT("De la inspección realizada podemos indicar las siguientes conclusiones:"," Realizar el mantenimiento periodico a fin de mejorar e incrementar la vida útil del ",'A-D.- FICHA'!J10:L10,", a continuacion detallamos las acciones a realizar.")
B56: FECHA INSPECCION : | D56: ='A-D.- FICHA'!N32

Sheet AUXILIAR
B3: ELLEMENTOS CONFORMANTES DE UN PUENTE Y SU IMPORTANCIA
B4: Item | C4: Codif. Elemento | D4: 1 | E4: Unidad | F4: Factor Importancia | G4: ELEMENTO
B5: 1 | C5: 101 | D5: Losa de concreto armado (Refuerzo longitudinal) | E5: m3 | F5: 1 | G5: SUPERESTRUCTURA
B6: =1+B5 | C6: 102 | D6: Losa de concreto pretensado (Pretensado Longitudinal) | E6: m3 | F6: 1 | G6: SUPERESTRUCTURA | I6: MACRO
B7: =1+B6 | C7: 103 | D7: Losa de Concreto Simple | E7: m3 | F7: 0.6 | G7: SUPERESTRUCTURA
B8: =1+B7 | C8: 104 | D8: Losa de concreto armado (Refuerzo Transversal) | E8: m3 | F8: 0.6 | G8: SUPERESTRUCTURA
B9: =1+B8 | C9: 105 | D9: Losa de concreto pretensado (Pretensado Transversal) | E9: m3 | F9: 0.6 | G9: SUPERESTRUCTURA
B10: =1+B9 | C10: 106 | D10: Plancha Metálica Corrugada | E10: m2 | F10: 0.6 | G10: SUPERESTRUCTURA
B11: =1+B10 | C11: 107 | D11: Tablero de Madera | E11: ft.2 | F11: 0.6 | G11: SUPERESTRUCTURA
B12: =1+B11 | C12: 110 | D12: Viga Principales concreto armado | E12: m3 | F12: 1 | G12: SUPERESTRUCTURA
B13: =1+B12 | C13: 111 | D13: Vigas Secundarias de concreto armado | E13: m3 | F13: 0.8 | G13: SUPERESTRUCTURA
B14: =1+B13 | C14: 112 | D14: Vigas Principales de concreto pretensado | E14: m3 | F14: 1 | G14: SUPERESTRUCTURA
B15: =1+B14 | C15: 113 | D15: Vigas Secundarias de concreto Pretensado | E15: m3 | F15: 0.8 | G15: SUPERESTRUCTURA
B16: =1+B15 | C16: 114 | D16: Vigas Principales de Acero Estructural | E16: kg | F16: 1 | G16: SUPERESTRUCTURA
B17: =1+B16 | C17: 115 | D17: Vigas Secundarias de Acero | E17: kg | F17: 0.8 | G17: SUPERESTRUCTURA
B18: =1+B17 | C18: 116 | D18: Vigas de Madera | E18: ft.2 | F18: 1 | G18: SUPERESTRUCTURA
... B116: =1+B115 | C116: 530 | D116: Visibilidad | E116: ml | F116: 0.2 | G116: ACCESOS

Sheet Hoja1
E2: GUIA PARA LA INSPECCION, EVALUACION Y MANTENIMIENTO DE PUENTES
A6: METODOLOGÍA PARA EVALUACION DE PUENTES
A8: CONDICION ESTADISTICA DE LOS ELEMENTOS Y DEL PUENTE
A10: Algoritmos para el análisis.
A12: En esta sección se describe los principales criterios empleados para las opciones de análisis. Los criterios y metodologías, se utilizan al escribir los códigos.
A15: 1 - Concepto de condición estadística
A17: Está sección del presente Manual contiene una explicación y fundamentación ampliada respecto a los procedimientos de cálculo para encontrar un numero que califique la condición, sea de un elemento como del puente.
A21: Se introduce el concepto de condición estadística, como aquel numero que califique la situación del puente y de cada uno de sus elementos. Este valor se deduce de la condición en campo, que corresponde a varios números, expresados en la forma de porcentajes de la situación del elemento en la escala de 0 a 5.
A26: En la condición en campo, la situación del elemento está definida por porcentajes, uno para cada escala. Está condición, está relacionada directamente con las necesidades de reparación o sustitución del elemento.
A30: La condición estadística, corresponde a un solo número que calificaría situación integral del elemento. Es utilizada para el cálculo de la condición del puente, y de ahí para la priorización. Obsérvese que puede darse el caso de varias condiciones de campo que conduzcan a un mismo valor de condición estadística.
A35: En esta sección se describen los criterios y metodologías empleados para las opciones de análisis.
A37: 2 - Condición estadística de un elemento
A39: Como se menciono, se introduce el concepto de condición estadística que simplifica en un número, la información de la condición del elemento proveniente, del trabajo de campo.
A42: La condición del elemento evaluada en campo, se expresa, según se ilustra en la Tabla 1, para un puente hipotético, como porcentajes para cada nivel de condición, desde 0 (muy bueno), hasta 5 (muy pobre). Así, el elemento 101, tiene el 10% en calidad satisfactoria, el 40% como bueno y el 50% como muy bueno.
B47: Tabla 1
B48: Ejemplo para la condición de cuatro elementos de un puente, según evaluación de campo.
B49: Porcentajes de la condición para cada elemento
A50: Elemento | C50: Nivel de la condición
C51: 5 | D51: 4 | E51: 3 | F51: 2 | G51: 1 | H51: 0 | I51: Total %
C52: Muy pobre | D52: Pobre | E52: Marginal | F52: Satisfactorio | G52: Bueno | H52: Muy Bueno
A53: 101 | C53: 0 | D53: 0 | E53: 0 | F53: 10 | G53: 40 | H53: 50 | I53: =SUM(C53:H53)
A54: 201 | C54: 0 | D54: 20 | E54: 20 | F54: 20 | G54: 20 | H54: 20 | I54: =SUM(C54:H54)
A55: 301 | C55: 10 | D55: 20 | E55: 50 | F55: 20 | G55: 0 | H55: 0 | I55: =SUM(C55:H55)
A56: 401 | C56: 2 | D56: 10 | E56: 28 | F56: 30 | G56: 20 | H56: 10 | I56: =SUM(C56:H56)
A57: 501 | C57: 0 | D57: 0 | E57: 40 | F57: 30 | G57: 20 | H57: 10 | I57: =SUM(C57:H57)
A59: La intención es expresar está situación dispersa, en un solo número que represente la condición global de cada elemento. EI procedimiento adoptado por el SCAP, es como sigue:
A63: UNIDAD GERENCIAL DE CONSERVACION | I63: 192
A64: AREA DE CONSERVACION DE PUENTES
E67: GUIA PARA LA INSPECCION, EVALUACION Y MANTENIMIENTO DE PUENTES
A71: 2.1 | B71: EI primer paso corresponde a ajustar la distribución de porcentajes, a condiciones umbral. Este ajuste se basa en la percepción, de que si un porcentaje significativo de un elemento está en un nivel dado de condición, entonces el elemento debiera ser evaluado como si totalmente estuviera en esa condición. EI proceso de ajuste corresponde a dividir el porcentaje de distribución de campo por aquel del umbral, y multiplicar el resultado por 100.
B77: Adoptamos un umbral del 3% para el nivel de condición 5, y 25% para los otros estados. Esto significa, por ejemplo, que basta que el 3% del elemento este en la condición 5 (muy pobre), para considerar está situación como la del total del elemento.
B81: Igualmente, si el 25% del elemento está en la condición 4 (pobre), está será la condición del elemento.
B84: El resultado del primer paso para el ejemplo, se muestra en la siguiente Tabla 2.
B86: Tabla 2
B87: Ajustes según porcentaje de umbral (%campo * 100 / %umbral)
B88: Porcentajes ajustados de la condición para cada elemento
A89: Elemento | C89: Nivel de la condición
C90: 5 | D90: 4 | E90: 3 | F90: 2 | G90: 1 | H90: 0 | L90: 5 | M90: 4 | N90: 3 | O90: 2 | P90: 1 | Q90: 0
C91: Muy pobre | D91: Pobre | E91: Marginal | F91: Satisfactorio | G91: Bueno | H91: Muy Bueno | L91: Muy pobre | M91: Pobre | N91: Marginal | O91: Satisfactorio | P91: Bueno | Q91: Muy Bueno
A92: 101 | C92: =ROUNDDOWN(+C53*100/3,0) | D92: =ROUNDDOWN(+D53*100/25,0) | E92: =ROUNDDOWN(+E53*100/25,0) | F92: =ROUNDDOWN(+F53*100/25,0) | G92: =ROUNDDOWN(+G53*100/25,0) | H92: =ROUNDDOWN(+H53*100/25,0) | L92: =+C92 | M92: =+C92+D92 | N92: =+C92+D92+E92 | O92: =+C92+D92+E92+F92 | P92: =+C92+D92+E92+F92+G92 | Q92: =+C92+D92+E92+F92+G92+H92
...

Sheet Hoja3
B2: UBICACIÓN GENERAL DEL PUENTE
B3: Distrito: | C3: =+'A-D.- FICHA'!J20
B4: Provincia: | C4: =+'A-D.- FICHA'!J18
B5: Departamento Político: | C5: =+'A-D.- FICHA'!J14
B6: Departamento Vial: | C6: =+'A-D.- FICHA'!J16
B7: Ruta: | C7: =+'A-D.- FICHA'!P16
B8: Tipo de Ruta: | C8: =+'A-D.- FICHA'!P20
B9: Tramo: | C9: =+'A-D.- FICHA'!E20
B10: Progresiva: | C10: =+'A-D.- FICHA'!P18
B11: Puente: | C11: =+'A-D.- FICHA'!J10
B12: DESCRIPCION DE LA SUPERESTRUCTURA
B13: Tipo: | C13: =+'A-D.- FICHA'!E79
B14: Material: | C14: =+'A-D.- FICHA'!E85
B15: N° de vanos: | C15: =+'A-D.- FICHA'!E63
B16: Condición de borde: | C16: =+'A-D.- FICHA'!E83
B17: Longitud Total: | C17: =+'A-D.- FICHA'!E67
B18: Calzada: | C18: =+'A-D.- FICHA'!E103
B19: N° Vías: | C19: =+'A-D.- FICHA'!E34
B20: Sobre Carga Diseño: | C20: =+'A-D.- FICHA'!E38
B21: Espesor de Losa: | C21: =+'A-D.- FICHA'!E101
B22: Eje de Viga(s) | C22: =+'A-D.- FICHA'!P105
B23: Altura de Viga(s) | C23: =+'A-D.- FICHA'!J107
B24: N° Vigas | C24: =+'A-D.- FICHA'!J101
B25: DESCRIPCCION DE LA INFRAESTRUCTURA
B26: Estribos: | C26: =+'A-D.- FICHA'!J121
B27: Pilares: | C27: =IF(+'A-D.- FICHA'!G184=0,"No aplica",+'A-D.- FICHA'!G184=0)
