Workbook
Name Alineamiento: 'A-D.- FICHA'!$G$50:$H$52
Name Alineamiento: #REF!
Name CatTipo: 'A-D.- FICHA'!$E$134:$R$134
Name CatTipo: #REF!
Name Cond.Borde: 'A-D.- FICHA'!$C$145:$C$151
Name Cond.Borde: #REF!
Name Cond.Carretera: 'A-D.- FICHA'!$J$376:$J$378
Name Cond.Carretera: #REF!
Name CondAmb: 'A-D.- FICHA'!$N$50:$N$52
Name CondAmb: #REF!
Name elementos: #REF!
Name FormaViga: 'A-D.- FICHA'!$L$154:$L$157
Name FormaViga: #REF!
Name luisa: 'A-D.- FICHA'!$C$162:$C$166
Name luisa: #REF!
Name MarcasdeCalzada: 'A-D.- FICHA'!$G$373
Name MarcasdeCalzada: #REF!
Name Mat: 'A-D.- FICHA'!$G$162:$G$165
Name Mat: #REF!
Name Mat.Predo: 'A-D.- FICHA'!$G$145:$G$152
Name Mat.Predo: #REF!
Name MatBaranda: 'A-D.- FICHA'!$G$283:$G$286
Name MatBaranda: #REF!
Name MatDrenaje: 'A-D.- FICHA'!$M$291:$M$294
Name MatDrenaje: #REF!
Name MaterialCimenta: 'A-D.- FICHA'!$N$162:$N$166
Name MaterialCimenta: #REF!
Name MaterialEleva: 'A-D.- FICHA'!$G$162:$G$165
Name MaterialEleva: #REF!
Name Materiallosa: 'A-D.- FICHA'!$J$145:$J$149
Name Materiallosa: #REF!
Name MatJuntas: 'A-D.- FICHA'!$F$291:$F$294
Name MatJuntas: #REF!
Name MatVeredas: 'A-D.- FICHA'!$J$283:$J$285
Name MatVeredas: #REF!
Name MatVigas: 'A-D.- FICHA'!$H$154:$H$158
Name MatVigas: #REF!
Name Nat.Suelo: 'A-D.- FICHA'!$N$376:$N$381
Name Nat.Suelo: #REF!
Name pendiente: #REF!
Name pendiente: #REF!
Name SeñaCarga: #REF!
Name SeñaCarga: #REF!
Name SeñalInformativa: 'A-D.- FICHA'!$G$361
Name SeñalInformativa: #REF!
Name Señalpreventiva: 'A-D.- FICHA'!$G$363:$G$366
Name Señalpreventiva: #REF!
Name SeñalReglamentaria: 'A-D.- FICHA'!$G$368:$G$371
Name SeñalReglamentaria: #REF!
Name Sobre: 'A-D.- FICHA'!$C$50:$E$57
Name Sobre: #REF!
Name Subestructura: 'A-D.- FICHA'!$G$376:$G$377
Name Subestructura: #REF!
Name SuperDesgaste: 'A-D.- FICHA'!$N$145:$N$149
Name SuperDesgaste: #REF!
Name TipoApoyos: 'A-D.- FICHA'!$N$283:$N$288
Name TipoApoyos: #REF!
Name TipoBarandas: 'A-D.- FICHA'!$C$283:$C$286
Name TipoBarandas: #REF!
Name TipoCimentación: 'A-D.- FICHA'!$J$162:$J$165

Sheet A-D.- FICHA
F1: SERVICIO DE CONSULTORIA PARA EL INVENTARIO ESPECIALIZADO DE LA INFRAESTRUCTURA VIAL EN LOS TRAMOS DE LA RED VIAL NACIONAL NO CONCESIONADA
C4: FICHA SCAP
C7: SECCION (A) : IDENTIFICACIÓN Y UBICACIÓN
H10: Nombre | J10: PUENTE | N10: 1
H12: Código | J12: PE-3N - 01 | N12: 2
C14: Altitud: | G14: 3 | H14: Dpto Político: | J14: LIMA | L14: 6 | N14: Pob. mas cercano | P14: =+J20 -> Matalaque | R14: 10
C16: Latitud | G16: 4 | H16: Dpto Vial | J16: LIMA | L16: 7 | N16: Ruta | P16: 3N | R16: 11
C18: Longitud | G18: 5 | H18: Provincia | J18: LIMA | L18: 8 | N18: Kilometraje | P18: 30298 | R18: 12
H20: Distrito | J20: Matalaque | L20: 9 | N20: Tipo de Ruta | P20: Nacional | R20: 13
C25: SECCION (B): DATOS GENERALES
C28: Puente sobre: | E28: Río | G28: 1 | J28: Número de Proyecto: | N28: 124-2026-MTC/20.2 | P28: 10
C30: Nombre: | E30: Tambo | G30: 2 | J30: Año de Construcción: | N30: Sin Informacion | P30: 11
C32: Longitud Total: | E32: 31.2 | G32: 3 | J32: Última Inspección: | N32: 46308 | P32: 12 | R32: mm/dd/aa
C34: Num de vías de tránsito: | E34: 1 | G34: 4 | J34: Último Trabajo: | N34: Sin Informacion | P34: 13
C36: Ancho de Calzada: | E36: 3.5 | G36: 5 | J36: Tipo de Servicio: | N36: Camiones hasta Cierta Carga | R36: 14
C38: Sobrecarga de Diseño: | E38: N/A | G38: 6 | J38: Flujo de Tráfico: | N38: SIN DATOS | P38: 15
C40: Ancho de Vereda: | E40: N/A | G40: 7 | J40: Año: | N40: 2026 | P40: 16
C42: Altura Libre Superior: | G42: 8 | J42: % Camiones y Buses: | N42: SIN DATOS | P42: 17
C44: Altura Libre Inferior: | E44: 5.63 | G44: 9 | J44: Alineamiento: | N44: Recto | P44: 18
J46: Condiciones Ambientales: | N46: Moderado | P46: 19
C49: Sobre | G49: Alineamiento | J49: Tipo de Servicio | N49: Condiciones Ambientales
C50: Río | G50: Recto | J50: Irrestricto | N50: Severo
C51: Quebrada Seca | G51: Curvo | J51: Solo Automoviles | N51: Moderado | R51: Tipo de ruta
C52: Quebrada | G52: Esviado | J52: Solo Camiones | N52: Benigno | R52: Nacional
C53: Canal | J53: Camiones hasta Cierta Carga | R53: Departamental
C54: Carretera | J54: Fuera de Servicio | R54: Vecinal
C55: FFCC
C56: Valle (Viaducto Elevado)
C57: Zona Urbana (Viaducto elevado)
C60: SECCION (C): DATOS DEL PUENTE
C63: Num Tram: | E63: 1 | G63: 1 | H63: Long. 1ºTramo: | J63: =+E67 -> 31.2 | L63: 4
C65: Tramos: | E65: Iguales | G65: 2 | H65: Long. 2ºTramo: | J65: - | L65: 5
C67: Longitud Total: | E67: =+E32 -> 31.2 | G67: (Igual a B-3) | H67: Long. 3ºTramo: | J67: - | L67: 6
C69: Luz Principal: | E69: 30.45 | G69: 3
C73: C.1 : TRAMO 1 (PRINCIPAL) | J73: C.2 :TRAMO 2
C75: {Sección 1} | J75: {Sección 2} | L75: =+IF(E65="Desiguales","","(igual a Sección 1)") -> (igual a Sección 1) | U75: DEFINITIVO
C76: {Subsección a} | J76: NO TIENE | U76: Losa
C77: Categoría: | E77: PROVISIONALES | G77: 1 | J77: Categoría: | P77: 1 | U77: Losa con Vigas
U78: Portico
C79: Tipo : | E79: Modular | G79: 2 | J79: Tipo : | P79: 2 | U79: Arco
...

Sheet E.- CROQUIS
D2: SERVICIO DE CONSULTORIA PARA EL INVENTARIO ESPECIALIZADO DE LA INFRAESTRUCTURA VIAL EN LOS TRAMOS DE LA RED VIAL NACIONAL NO CONCESIONADA
A5: FICHA SCAP
B8: SECCION ( E ) : CROQUIS DEL PUENTE
B9: NOMBRE : | C9: =+'A-D.- FICHA'!J10 -> PUENTE
B10: Ruta : | C10: =+'A-D.- FICHA'!P16 -> 3N | H10: Progresiva : | I10: =+'A-D.- FICHA'!P18 -> 30298
B12: ELEVACION
B26: PLANTA
B41: SECCION TRANSVERSAL
B55: =+'A-D.- FICHA'!C48 -> 0

Sheet F.1- CONDICION GLOBAL
E1: SERVICIO DE CONSULTORIA PARA EL INVENTARIO ESPECIALIZADO DE LA INFRAESTRUCTURA VIAL EN LOS TRAMOS DE LA RED VIAL NACIONAL NO CONCESIONADA
A4: FICHA SCAP
A5: SECCION (F): CONDICION DEL PUENTE
C6: Puente : | D6: =+#REF! -> #REF! | F6: Ruta : | G6: =+'A-D.- FICHA'!P16 -> 3N | I6: Progresiva: | K6: =+'A-D.- FICHA'!P18 -> 30298
C8: F.2 :CONDICION GLOBAL DEL PUENTE
D11: 1 | E11: Bueno | G11: 3 | H11: Preocupante | J11: 5 | K11: Pesimo
D13: 0 | E13: Excelente | G13: 2 | H13: Regular | J13: 4 | K13: Malo
C15: Inspector | H15: Fecha de Inspeccion | K15: ='A-D.- FICHA'!N32 -> 46308
C16: Supervisor | H16: Fecha de Revision
C19: Elemento | F19: Descripcion
B21: I. SUPERESTRUCTURA
B22: 168 | C22: Estructura Metálica Bailey | F22: Toda la superficie del piso se encuentra tapada por un conglomerado de piedras chancadas y tierra. Por otro lado presenta corrosión en un poste.
B23: II. SUBESTRUCTURA
B24: 201 | C24: Elevación Cuerpo del Estribo de Concreto Simple | F24: Tanto el apoyo izquierdo como el apoyo de derecho se encuentran sobre sus respectivos estribos cubiertas por un relleno excesivo que puede generar daños. Puede apreciarse crecimiento de musgos y problemas de intemperismo en el estribo izquierdo y derecho
B26: III. DETALLES
B27: 324 | C27: Apoyo articulado de acero | F27: El relleno de boloneria y tierra que se encuentran sobre el estribo derecho es de 90 cm. La acumulación de estos solidos puede afectar la estructura. Se recomienda limpieza.
B28: 341 | C28: Planchas Deslizantes | F28: Las juntas de dilatación o expansión son los espacios que existen entre puente y puente o entre puente y estribo, y sirven para absorber las fuerzas que se producen ya sea por efectos dinámicos o por sismo. En este caso ambas juntas se encuentran cubiertas por barro lo cual no permitiría el correcto trabajo de estos elementos.
B29: IV. CAUCE
B30: 401 | C30: Márgenes del río | F30: Las márgenes del río no son estables y tampoco alineadas evidenciada. Ambas márgenes son de material rocoso que al paso de las aguas y por el mismo terreno se desestabiliza, siendo necesario entonces proteger los márgenes.
B31: 402 | C31: Lecho del río | F31: Es un río con desembocadura en el río y presenta poca pendiente, el flujo de las aguas en épocas de lluvia es fuerte lo que está produciendo degradación y erosiones del lecho del río.
B33: V. ACCESOS
B34: 501 | C34: Señalización | F34: La señalización en sus diversas formas es un componente muy importante para el buen servicio de los puentes, pues constituye elementos de seguridad para el usuario y protegen indirectamente a la estructura. Para este caso se cuenta con las señales informativas y preventivas reglamentarias ambas en buen estado de conservación. Pueden apreciarse que la cimentación del esta con los aceros expuestos.
B35: 510 | C35: Muro de Concreto Armado en accesos | F35: Los muros contra impacto se considerarán elementos preventivos que constituyen un elemento de seguridad y protección de la estructura. Estas estructuras se encuentran cubiertas bajo una capa de 60 cm a 100 cm de altura.
B36: 511 | C36: Pavimento/Afirmado | F36: En el acceso izquierdo se ha acumulado una gran cantidad de material de relleno, lo que dificulta la transitabilidad. Además, se observan cárcavas que afectan la estabilidad del acceso.
B37: 530 | C37: Visibilidad | F37: Debido al alineamiento curvo en los accesos, la visibilidad desde el puente es regular, lo que podría representar un riesgo para la circulación vehicular.

Sheet F.2.-PANEL FOTOGRAFICO
D1: SERVICIO DE CONSULTORIA PARA EL INVENTARIO ESPECIALIZADO DE LA INFRAESTRUCTURA VIAL EN LOS TRAMOS DE LA RED VIAL NACIONAL NO CONCESIONADA
B3: F.2 PANEL FOTOGRAFICO | XFD3: SI
XFD4: NO
B5: NOMBRE | D5: =+'A-D.- FICHA'!J10 -> PUENTE
B6: RUTA | D6: =+'A-D.- FICHA'!P16 -> 3N
B7: PROGRESIVA | D7: =+'A-D.- FICHA'!P18 -> 30298
B9: LISTA DE FOTOGRAFIAS
B10: NRO. | C10: FECHA | D10: DESCRIPCION | E10: DIGITAL
B11: 1 | C11: 45715 | D11: ACCESO IZQUIERDO: Debido al alineamiento curvo la visibilidad desde el puente es regular, lo que podría representar un riesgo para la circulación vehicular.
B12: 2 | C12: 45715 | D12: AFIRMADO ACCESO IZQUIERDO: En el acceso izquierdo se ha acumulado una gran cantidad de material de relleno, lo que dificulta la transitabilidad. Además, se observan cárcavas que afectan la estabilidad del acceso.
B13: 3 | C13: 45715 | D13: ACCESO DERECHO: Debido al alineamiento curvo la visibilidad desde el puente es regular, lo que podría representar un riesgo para la circulación vehicular.
B14: 4 | C14: 45715 | D14: AFIRMADO ACCESO DERECHO: No se observa daños en el afirmado del acceso derecho.
B15: 5 | C15: 45715 | D15: SUPERFICIE DE RODARURA: Se ha acumulado material de relleno a lo largo de la superficie de rodadura, llegando hasta el borde superior de la vereda. Esto ha generado encharcamiento de agua en la superficie de rodadura, además de obstrucción parcial y total en el ingreso del sistema de drenaje.
B16: 6 | C16: 45715 | D16: AGUAS ARRIBA: Márgenes están bien definidas, ya que el terreno es rocoso. Se presenta un caudal torrentoso que transporta material de gran tamaño, lo que podría generar cambios en la estabilidad del cauce en eventos de alta precipitación.
B17: 7 | C17: 45715 | D17: AGUAS ABAJO: Margen izquierda aguas abajo se encuentra material de relleno del talud de la carretera, el cual es altamente erosionable. Se presenta un caudal torrentoso que transporta material de gran tamaño, lo que podría generar cambios en la estabilidad del cauce en eventos de alta precipitación.
B18: 8 | C18: 45715 | D18: ALA IZQUIERDA AGUAS ARRIBA: Se observa decoloración del concreto y acumulación de polvo en la superficie. Además, se presentan rastros de eflorescencia.
B19: 9 | C19: 45715 | D19: ALA DERECHA AGUAS ARRIBA: Se observa decoloración del concreto y acumulación de polvo en la superficie. Además, se presentan rastros de eflorescencia.
B20: 10 | C20: 45715 | D20: ALA IZQUIERDA AGUAS ABAJO: Se observa decoloración del concreto y acumulación de polvo en la superficie. Además, se presentan rastros de eflorescencia.
B21: 11 | C21: 45715 | D21: ALA DERECHA AGUAS ABAJO: Se observa decoloración del concreto y acumulación de polvo en la superficie. Además, se presentan rastros de eflorescencia.
B22: 12 | C22: 45715 | D22: PANTALLA DE ESTRIBO IZQUIERDO: Se observa decoloración del concreto y acumulación de polvo en la superficie.
... B42: 32 | C42: 45715 | D42: SEÑAL INFORMATIVA DEL ACCESO IZQUIERDO: Solo se cuenta con un cartel informativo en el acceso izquierdo, indicando el nombre, la longitud y la capacidad máxima del puente. Los postes con picaduras de oxido.

Sheet G.- CONDICION ESTADISTICA
C1: SERVICIO DE CONSULTORIA PARA EL INVENTARIO ESPECIALIZADO DE LA INFRAESTRUCTURA VIAL EN LOS TRAMOS DE LA RED VIAL NACIONAL NO CONCESIONADA
A3: =+'A-D.- FICHA'!C4 -> FICHA SCAP
A5: G.1 : CONDICION ESTADISTICA DEL PUENTE
A7: =+CONCATENATE("NOMBRE: ",'A-D.- FICHA'!J10) -> NOMBRE: PUENTE | E7: Ruta: | F7: =+'A-D.- FICHA'!P16 -> 3N | J7: PROGRESIVA : | M7: =+'A-D.- FICHA'!P18 -> 30298
A9: tabla 1
A10: CODIGO | B10: DESCRIPCION | D10: METRADO | E10: UND. | F10: Factor de Importancia | G10: CALIFICACION (%) | M10: CONDICION ESTADISTICA DEL PUENTE
G11: 0 | H11: 1 | I11: 2 | J11: 3 | K11: 4 | L11: 5
G12: Muy Bueno | H12: Bueno | I12: Satisfactorio | J12: Marginal | K12: Pobre | L12: Muy Pobre | N12: =IF(M13>4,"MUY MALO",IF(M13>3,"MALO",IF(M13>2,"REGULAR","BUENO"))) -> BUENO
M13: =+F191 -> 1.5554252 | O13: verificaciones
A14: 168 | B14: Estructura Metálica Bailey | D14: =4.7*0.2*31.2 -> 29.328 | E14: und | F14: 1 | G14: 90 | H14: 10 | O14: =SUM(G14:L14) -> 100 | P14: =+IF(O14<=100,+IF(O14=100,"Ok",""),"se pasa") -> Ok
A15: 201 | B15: Elevación Cuerpo del Estribo de Concreto Simple | D15: =66.05*0.5*2 -> 66.05 | E15: m3 | F15: 1 | G15: 70 | H15: 30 | O15: =SUM(G15:L15) -> 100 | P15: =+IF(O15<=100,+IF(O15=100,"Ok",""),"se pasa") -> Ok
A16: 324 | B16: Apoyo articulado de acero | D16: =0.375*5*3.5 -> 6.5625 | E16: und | F16: 0.4 | G16: 50 | I16: 50 | O16: =SUM(G16:L16) -> 100 | P16: =+IF(O16<=100,+IF(O16=100,"Ok",""),"se pasa") -> Ok
A17: 341 | B17: Planchas Deslizantes | D17: =12.78*2*4.7 -> 120.132 | E17: ml | F17: 0.4 | I17: 100 | O17: =SUM(G17:L17) -> 100 | P17: =+IF(O17<=100,+IF(O17=100,"Ok",""),"se pasa") -> Ok
A18: 401 | B18: Márgenes del río | D18: =3.5*0.3*5.3*4 -> 22.26 | E18: ml | F18: 0.6 | H18: 100 | O18: =SUM(G18:L18) -> 100 | P18: =+IF(O18<=100,+IF(O18=100,"Ok",""),"se pasa") -> Ok
A19: 402 | B19: Lecho del río | D19: =31.2*3.5 -> 109.2 | E19: ml | F19: 0.6 | G19: 70 | H19: 30 | O19: =SUM(G19:L19) -> 100 | P19: =+IF(O19<=100,+IF(O19=100,"Ok",""),"se pasa") -> Ok
A20: 501 | B20: Señalización | D20: =31.2*0.6*2 -> 37.44 | E20: und | F20: 0.2 | G20: 100 | O20: =SUM(G20:L20) -> 100 | P20: =+IF(O20<=100,+IF(O20=100,"Ok",""),"se pasa") -> Ok
A21: 504 | B21: Muro de Concreto Armado en accesos | D21: =2*31.2 -> 62.4 | E21: m3 | F21: 0.6 | G21: 50 | H21: 50 | O21: =SUM(G21:L21) -> 100 | P21: =+IF(O21<=100,+IF(O21=100,"Ok",""),"se pasa") -> Ok
A22: 511 | B22: Pavimento/Afirmado | D22: 0 | E22: m2 | F22: 0.2 | H22: 80 | I22: 20 | O22: =SUM(G22:L22) -> 100 | P22: =+IF(O22<=100,+IF(O22=100,"Ok",""),"se pasa") -> Ok
A23: 530 | B23: Visibilidad | D23: 2 | E23: ml | F23: 0.2 | H23: 80 | I23: 20 | O23: =SUM(G23:L23) -> 100 | P23: =+IF(O23<=100,+IF(O23=100,"Ok",""),"se pasa") -> Ok
O24: =SUM(G24:L24) -> 0 | P24: =+IF(O24<=100,+IF(O24=100,"Ok",""),"se pasa")
O25: =SUM(G25:L25) -> 0 | P25: =+IF(O25<=100,+IF(O25=100,"Ok",""),"se pasa")
O26: =SUM(G26:L26) -> 0 | P26: =+IF(O26<=100,+IF(O26=100,"Ok",""),"se pasa")
O27: =SUM(G27:L27) -> 0 | P27: =+IF(O27<=100,+IF(O27=100,"Ok",""),"se pasa")
O28: =SUM(G28:L28) -> 0 | P28: =+IF(O28<=100,+IF(O28=100,"Ok",""),"se pasa")
O29: =SUM(G29:L29) -> 0 | P29: =+IF(O29<=100,+IF(O29=100,"Ok",""),"se pasa")
O30: =SUM(G30:L30) -> 0 | P30: =+IF(O30<=100,+IF(O30=100,"Ok",""),"se pasa")
O31: =SUM(G31:L31) -> 0 | P31: =+IF(O31<=100,+IF(O31=100,"Ok",""),"se pasa")
O32: =SUM(G32:L32) -> 0 | P32: =+IF(O32<=100,+IF(O32=100,"Ok",""),"se pasa")
O33: =SUM(G33:L33) -> 0 | P33: =+IF(O33<=100,+IF(O33=100,"Ok",""),"se pasa")
O34: =SUM(G34:L34) -> 0 | P34: =+IF(O34<=100,+IF(O34=100,"Ok",""),"se pasa")
O35: =SUM(G35:L35) -> 0 | P35: =+IF(O35<=100,+IF(O35=100,"Ok",""),"se pasa")
E36: =+IF(A36=0," ",VLOOKUP(A36,#REF!,7)) | O36: =SUM(G36:L36) -> 0 | P36: =+IF(O36<=100,+IF(O36=100,"Ok",""),"se pasa")
E37: =+IF(A37=0," ",VLOOKUP(A37,#REF!,7))
E38: =+IF(A38=0," ",VLOOKUP(A38,#REF!,7))
E39: =+IF(A39=0," ",VLOOKUP(A39,#REF!,7))
E40: =+IF(A40=0," ",VLOOKUP(A40,#REF!,7))
E41: =+IF(A41=0," ",VLOOKUP(A41,#REF!,7))
E42: =+IF(A42=0," ",VLOOKUP(A42,#REF!,7))
E43: =+IF(A43=0," ",VLOOKUP(A43,#REF!,7))
E44: =+IF(A44=0," ",VLOOKUP(A44,#REF!,7))
...

Sheet G.2-CONCLUSIONES
D1: SERVICIO DE CONSULTORIA PARA EL INVENTARIO ESPECIALIZADO DE LA INFRAESTRUCTURA VIAL EN LOS TRAMOS DE LA RED VIAL NACIONAL NO CONCESIONADA
B4: FICHA SCAP
B6: SECCION (G): RESUMEN DE LA CONDICION DEL PUENTE Y RECOMENDACIONES
C9: G.2 : OBSERVACIONES Y RECOMENDACIONES
B12: NOMBRE | D12: =+Hoja3!C11 -> PUENTE
B13: RUTA | D13: =+Hoja3!C7 -> 3N
B14: PROGRESIVA | D14: =+Hoja3!C10 -> 30298
B17: OBSERVACIONES | F17: RECOMENDACIONES
B18: ACCIONES NORMATIVAS :
B19: De la inspección realizada podemos indicar las siguientes conclusiones y recomendaciones: • La evaluación de la condición estadística del puente, efectuada bajo la metodología SCAP señala que el puente se encuentra en la calificación "& 'Secc G.1 Eval SCAP'!E205& ", requiriéndose realizar trabajos de reparación a fin de mejorar e incrementar su vida útil."
B28: * El muro de concreto armado que se encuentra en los accesos se encuentra en un estado malo estructuralmente, debido al acero expuesto. | E28: * Realizar reparacion del muro de concreto y pintarlo nuevamente.
B34: * Ausencia de señales preventivas y reglamentarias en ambos accesos. | E34: * Colocar señales preventivas y reglamentarias en ambos accesos.
B40: ACCIONES PREVENTIVAS :
B41: • La evaluación de la condición estadística del puente, efectuada bajo la metodología SCAP señala que el puente se encuentra en la calificación REGULAR, requiriéndose realizar el mantenimiento y algunos trabajos menores de reparación a fin de mejorar e incrementar su vida útil. | E41: • Debe limpiarse el piso metálico de la superestructura y reparar los elementos señalados. • Deben limpiarse la superficie de apoyo fijo que se encuentran obstruidos por bolonería y material de arrastre. • Se recomienda insertar en los bordes de los parapetos o junta que va hacia el piso metálico un ángulo metálico de protección, a fin de evitar posibles desprendimientos del concreto y desobstruirlas. • Efectuar una limpieza general eliminándose basura, malezas y arbustos que rodea al puente a fin de evitar los microclimas que dañan la estructura. • Hacer un hidrolavado general de la estructura.
B49: * Debera realizarse un mantenimiento de la superestructura, debido a que la superficie de desgaste se encuentra con suciedad. | E49: * Realizar limpieza en la superestructura del puente.
B51: * Los estribos deberan ser recubiertos por un material que no filtre el agua para que ya no se genere mas moho. | E51: * Debera cambiarse el muro de concreto armado que se encuentra en los accesos.
B53: * La estructura del puente se encuentra cubierto en parte por vegetacion. Esto dificulta futuros mantenimientos | E53: * Se debera disminuir la vegetacion para que esta no obstruya la vision de los conductores.
B55: ACCIONES EJECUTIVAS :
B56: * El muro de concreto armado presenta acero expuesto. | E56: =_xlfn.CONCAT("De la inspección realizada podemos indicar las siguientes conclusiones:"," Realizar el mantenimiento periodico a fin de mejorar e incrementar la vida útil del ",'A-D.- FICHA'!J10:L10,", a continuacion detallamos las acciones a realizar.") -> De la inspección realizada podemos indicar las siguientes conclusiones: Realizar el mantenimiento periodico a fin de mejorar e incrementar la vida útil del PUENTE, a continuacion detallamos las acciones a realizar.
B57: * El estribo presenta moho.
B58: * La estructura metalica presenta polvo impregnado.
B60: • Limpieza roce y desbroce. • Limpieza de puentes. • Reparación de deterioros superficiales en elementos de concreto. • Reparación de fisuras y grietas en elementos de concreto. | E60: * Realizar reparacion del muro.
E61: • Tratamiento con pintura cementicia con aditivo antibacterial.
E62: * Reparar el estribo utilizando concreto antifiltrante y fuerte contra sulfatos.
E63: * Limpieza de la estructura metalica.
B73: FECHA INSPECCION : | D73: ='A-D.- FICHA'!N32 -> 46308

Sheet AUXILIAR
B3: ELLEMENTOS CONFORMANTES DE UN PUENTE Y SU IMPORTANCIA
B4: Item | C4: Codif. Elemento | D4: 1 | E4: Unidad | F4: Factor Importancia | G4: ELEMENTO
B5: 1 | C5: 101 | D5: Losa de concreto armado (Refuerzo longitudinal) | E5: m3 | F5: 1 | G5: SUPERESTRUCTURA
B6: =1+B5 -> 2 | C6: 102 | D6: Losa de concreto pretensado (Pretensado Longitudinal) | E6: m3 | F6: 1 | G6: SUPERESTRUCTURA | I6: MACRO
B7: =1+B6 -> 3 | C7: 103 | D7: Losa de Concreto Simple | E7: m3 | F7: 0.6 | G7: SUPERESTRUCTURA
B8: =1+B7 -> 4 | C8: 104 | D8: Losa de concreto armado (Refuerzo Transversal) | E8: m3 | F8: 0.6 | G8: SUPERESTRUCTURA
B9: =1+B8 -> 5 | C9: 105 | D9: Losa de concreto pretensado (Pretensado Transversal) | E9: m3 | F9: 0.6 | G9: SUPERESTRUCTURA
B10: =1+B9 -> 6 | C10: 106 | D10: Plancha Metálica Corrugada | E10: m2 | F10: 0.6 | G10: SUPERESTRUCTURA
B11: =1+B10 -> 7 | C11: 107 | D11: Tablero de Madera | E11: ft.2 | F11: 0.6 | G11: SUPERESTRUCTURA
B12: =1+B11 -> 8 | C12: 110 | D12: Viga Principales concreto armado | E12: m3 | F12: 1 | G12: SUPERESTRUCTURA
B13: =1+B12 -> 9 | C13: 111 | D13: Vigas Secundarias de concreto armado | E13: m3 | F13: 0.8 | G13: SUPERESTRUCTURA
B14: =1+B13 -> 10 | C14: 112 | D14: Vigas Principales de concreto pretensado | E14: m3 | F14: 1 | G14: SUPERESTRUCTURA
B15: =1+B14 -> 11 | C15: 113 | D15: Vigas Secundarias de concreto Pretensado | E15: m3 | F15: 0.8 | G15: SUPERESTRUCTURA
B16: =1+B15 -> 12 | C16: 114 | D16: Vigas Principales de Acero Estructural | E16: kg | F16: 1 | G16: SUPERESTRUCTURA
B17: =1+B16 -> 13 | C17: 115 | D17: Vigas Secundarias de Acero | E17: kg | F17: 0.8 | G17: SUPERESTRUCTURA
B18: =1+B17 -> 14 | C18: 116 | D18: Vigas de Madera | E18: ft.2 | F18: 1 | G18: SUPERESTRUCTURA
... B116: =1+B115 -> 112 | C116: 530 | D116: Visibilidad | E116: ml | F116: 0.2 | G116: ACCESOS

Sheet Hoja1
E2: GUIA PARA LA INSPECCION, EVALUACION Y MANTENIMIENTO DE PUENTES
A6: METODOLOGÍA PARA EVALUACION DE PUENTES
A8: CONDICION ESTADISTICA DE LOS ELEMENTOS Y DEL PUENTE
A10: Algoritmos para el análisis.
A12: En esta sección se describe los principales criterios empleados para las opciones de análisis. Los criterios y metodologías, se utilizan al escribir los códigos.
A15: 1 - Concepto de condición estadística
A17: Está sección del presente Manual contiene una explicación y fundamentación ampliada respecto a los procedimientos de cálculo para encontrar un numero que califique la condición, sea de un elemento como del puente.
A21: Se introduce el concepto de condición estadística, como aquel numero que califique la situación del puente y de cada uno de sus elementos. Este valor se deduce de la condición en campo, que corresponde a varios números, expresados en la forma de porcentajes de la situación del elemento en la escala de 0 a 5.
A26: En la condición en campo, la situación del elemento está definida por porcentajes, uno para cada escala. Está condición, está relacionada directamente con las necesidades de reparación o sustitución del elemento.
A30: La condición estadística, corresponde a un solo número que calificaría situación integral del elemento. Es utilizada para el cálculo de la condición del puente, y de ahí para la priorización. Obsérvese que puede darse el caso de varias condiciones de campo que conduzcan a un mismo valor de condición estadística.
A35: En esta sección se describen los criterios y metodologías empleados para las opciones de análisis.
A37: 2 - Condición estadística de un elemento
A39: Como se menciono, se introduce el concepto de condición estadística que simplifica en un número, la información de la condición del elemento proveniente, del trabajo de campo.
A42: La condición del elemento evaluada en campo, se expresa, según se ilustra en la Tabla 1, para un puente hipotético, como porcentajes para cada nivel de condición, desde 0 (muy bueno), hasta 5 (muy pobre). Así, el elemento 101, tiene el 10% en calidad satisfactoria, el 40% como bueno y el 50% como muy bueno.
B47: Tabla 1
B48: Ejemplo para la condición de cuatro elementos de un puente, según evaluación de campo.
B49: Porcentajes de la condición para cada elemento
A50: Elemento | C50: Nivel de la condición
C51: 5 | D51: 4 | E51: 3 | F51: 2 | G51: 1 | H51: 0 | I51: Total %
C52: Muy pobre | D52: Pobre | E52: Marginal | F52: Satisfactorio | G52: Bueno | H52: Muy Bueno
A53: 101 | C53: 0 | D53: 0 | E53: 0 | F53: 10 | G53: 40 | H53: 50 | I53: =SUM(C53:H53) -> 100
A54: 201 | C54: 0 | D54: 20 | E54: 20 | F54: 20 | G54: 20 | H54: 20 | I54: =SUM(C54:H54) -> 100
A55: 301 | C55: 10 | D55: 20 | E55: 50 | F55: 20 | G55: 0 | H55: 0 | I55: =SUM(C55:H55) -> 100
A56: 401 | C56: 2 | D56: 10 | E56: 28 | F56: 30 | G56: 20 | H56: 10 | I56: =SUM(C56:H56) -> 100
A57: 501 | C57: 0 | D57: 0 | E57: 40 | F57: 30 | G57: 20 | H57: 10 | I57: =SUM(C57:H57) -> 100
A59: La intención es expresar está situación dispersa, en un solo número que represente la condición global de cada elemento. EI procedimiento adoptado por el SCAP, es como sigue:
A63: UNIDAD GERENCIAL DE CONSERVACION | I63: 192
A64: AREA DE CONSERVACION DE PUENTES
E67: GUIA PARA LA INSPECCION, EVALUACION Y MANTENIMIENTO DE PUENTES
A71: 2.1 | B71: EI primer paso corresponde a ajustar la distribución de porcentajes, a condiciones umbral. Este ajuste se basa en la percepción, de que si un porcentaje significativo de un elemento está en un nivel dado de condición, entonces el elemento debiera ser evaluado como si totalmente estuviera en esa condición. EI proceso de ajuste corresponde a dividir el porcentaje de distribución de campo por aquel del umbral, y multiplicar el resultado por 100.
B77: Adoptamos un umbral del 3% para el nivel de condición 5, y 25% para los otros estados. Esto significa, por ejemplo, que basta que el 3% del elemento este en la condición 5 (muy pobre), para considerar está situación como la del total del elemento.
B81: Igualmente, si el 25% del elemento está en la condición 4 (pobre), está será la condición del elemento.
B84: El resultado del primer paso para el ejemplo, se muestra en la siguiente Tabla 2.
B86: Tabla 2
B87: Ajustes según porcentaje de umbral (%campo * 100 / %umbral)
B88: Porcentajes ajustados de la condición para cada elemento
A89: Elemento | C89: Nivel de la condición
C90: 5 | D90: 4 | E90: 3 | F90: 2 | G90: 1 | H90: 0 | L90: 5 | M90: 4 | N90: 3 | O90: 2 | P90: 1 | Q90: 0
C91: Muy pobre | D91: Pobre | E91: Marginal | F91: Satisfactorio | G91: Bueno | H91: Muy Bueno | L91: Muy pobre | M91: Pobre | N91: Marginal | O91: Satisfactorio | P91: Bueno | Q91: Muy Bueno
A92: 101 | C92: =ROUNDDOWN(+C53*100/3,0) -> 0 | D92: =ROUNDDOWN(+D53*100/25,0) -> 0 | E92: =ROUNDDOWN(+E53*100/25,0) -> 0 | F92: =ROUNDDOWN(+F53*100/25,0) -> 40 | G92: =ROUNDDOWN(+G53*100/25,0) -> 160 | H92: =ROUNDDOWN(+H53*100/25,0) -> 200 | L92: =+C92 -> 0 | M92: =+C92+D92 -> 0 | N92: =+C92+D92+E92 -> 0 | O92: =+C92+D92+E92+F92 -> 40 | P92: =+C92+D92+E92+F92+G92 -> 200 | Q92: =+C92+D92+E92+F92+G92+H92 -> 400
...

Sheet Hoja3
B2: UBICACIÓN GENERAL DEL PUENTE
B3: Distrito: | C3: =+'A-D.- FICHA'!J20 -> Matalaque
B4: Provincia: | C4: =+'A-D.- FICHA'!J18 -> LIMA
B5: Departamento Político: | C5: =+'A-D.- FICHA'!J14 -> LIMA
B6: Departamento Vial: | C6: =+'A-D.- FICHA'!J16 -> LIMA
B7: Ruta: | C7: =+'A-D.- FICHA'!P16 -> 3N
B8: Tipo de Ruta: | C8: =+'A-D.- FICHA'!P20 -> Nacional
B9: Tramo: | C9: =+'A-D.- FICHA'!E20 -> 0
B10: Progresiva: | C10: =+'A-D.- FICHA'!P18 -> 30298
B11: Puente: | C11: =+'A-D.- FICHA'!J10 -> PUENTE
B12: DESCRIPCION DE LA SUPERESTRUCTURA
B13: Tipo: | C13: =+'A-D.- FICHA'!E79 -> Modular
B14: Material: | C14: =+'A-D.- FICHA'!E85 -> Perfiles Metálicos
B15: N° de vanos: | C15: =+'A-D.- FICHA'!E63 -> 1
B16: Condición de borde: | C16: =+'A-D.- FICHA'!E83 -> Simp. Apoyado
B17: Longitud Total: | C17: =+'A-D.- FICHA'!E67 -> 31.2
B18: Calzada: | C18: =+'A-D.- FICHA'!E103 -> Metálica
B19: N° Vías: | C19: =+'A-D.- FICHA'!E34 -> 1
B20: Sobre Carga Diseño: | C20: =+'A-D.- FICHA'!E38 -> N/A
B21: Espesor de Losa: | C21: =+'A-D.- FICHA'!E101 -> 5 pulg
B22: Eje de Viga(s) | C22: =+'A-D.- FICHA'!P105 -> 0
B23: Altura de Viga(s) | C23: =+'A-D.- FICHA'!J107 -> 0
B24: N° Vigas | C24: =+'A-D.- FICHA'!J101 -> 0
B25: DESCRIPCCION DE LA INFRAESTRUCTURA
B26: Estribos: | C26: =+'A-D.- FICHA'!J121 -> Gravedad
B27: Pilares: | C27: =IF(+'A-D.- FICHA'!G184=0,"No aplica",+'A-D.- FICHA'!G184=0) -> No aplica
